test_anagram (__main__.TestExercice) ... FAIL
test_doubles (__main__.TestExercice) ... ERROR
test_grades (__main__.TestExercice) ... ERROR
test_histogram (__main__.TestExercice) ... FAIL
test_order (__main__.TestExercice) ... ERROR

======================================================================
ERROR: test_doubles (__main__.TestExercice)
----------------------------------------------------------------------
Traceback (most recent call last):
  File "test_exercice.py", line 49, in test_doubles
    output = [exercice.contains_doubles(v) for v in values]
  File "test_exercice.py", line 49, in <listcomp>
    output = [exercice.contains_doubles(v) for v in values]
  File "/home/runner/work/c03_ch6_exercices-qyle-343/c03_ch6_exercices-qyle-343/exercice.py", line 28, in contains_doubles
    my_set = set(my_list)
NameError: name 'my_list' is not defined

======================================================================
ERROR: test_grades (__main__.TestExercice)
----------------------------------------------------------------------
Traceback (most recent call last):
  File "test_exercice.py", line 63, in test_grades
    output = [exercice.best_grades(v) for v in values]
  File "test_exercice.py", line 63, in <listcomp>
    output = [exercice.best_grades(v) for v in values]
  File "/home/runner/work/c03_ch6_exercices-qyle-343/c03_ch6_exercices-qyle-343/exercice.py", line 34, in best_grades
    for nom in grades:
NameError: name 'grades' is not defined

======================================================================
ERROR: test_order (__main__.TestExercice)
----------------------------------------------------------------------
Traceback (most recent call last):
  File "test_exercice.py", line 19, in test_order
    output = [exercice.order(v) for v in values]
  File "test_exercice.py", line 19, in <listcomp>
    output = [exercice.order(v) for v in values]
  File "/home/runner/work/c03_ch6_exercices-qyle-343/c03_ch6_exercices-qyle-343/exercice.py", line 16, in order
    return ordre
UnboundLocalError: local variable 'ordre' referenced before assignment

======================================================================
FAIL: test_anagram (__main__.TestExercice)
----------------------------------------------------------------------
Traceback (most recent call last):
  File "test_exercice.py", line 40, in test_anagram
    'Erreur dans la vérification de l\'anagramme'
AssertionError: Lists differ: [False, False] != [True, False]

First differing element 0:
False
True

- [False, False]
+ [True, False] : Erreur dans la vérification de l'anagramme

======================================================================
FAIL: test_histogram (__main__.TestExercice)
----------------------------------------------------------------------
Traceback (most recent call last):
  File "test_exercice.py", line 84, in test_histogram
    'Erreur dans les histogrammes'
AssertionError: [({}, []), ({}, [])] is not an instance of <class 'dict'> : First argument is not a dictionary

----------------------------------------------------------------------
Ran 5 tests in 0.001s

FAILED (failures=2, errors=3)
